<?xml version="1.0"?>
<robot xmlns:xacro="http://www.ros.org/wiki/xacro" name="robot">

  <!-- Materials -->
  <material name="white">
    <color rgba="1 1 1 1" />
  </material>
  <material name="blue">
    <color rgba="0.2 0.2 1 1" />
  </material>
  <material name="black">
    <color rgba="0 0 0 1" />
  </material>

  <!-- Base -->
  <link name="base_link" />

  <!-- Chassis -->
  <joint name="chassis_joint" type="fixed">
    <parent link="base_link" />
    <child link="chassis" />
    <origin xyz="0 0 0.075" />
  </joint>

  <link name="chassis">
    <visual>
      <geometry>
        <box size="0.3 0.3 0.15" />
      </geometry>
      <material name="white" />
    </visual>
    <collision>
      <geometry>
        <box size="0.3 0.3 0.15" />
      </geometry>
    </collision>
    <inertial>
      <mass value="1.0" />
      <inertia ixx="0.02" ixy="0" ixz="0"
        iyy="0.02" iyz="0"
        izz="0.02" />
    </inertial>
  </link>

  <!-- Left wheel -->
  <joint name="left_wheel_joint" type="continuous">
    <parent link="base_link" />
    <child link="left_wheel" />
    <origin xyz="0 0.175 0.05" rpy="1.5708 0 0" />
    <axis xyz="0 0 1" />
  </joint>

  <link name="left_wheel">
    <visual>
      <geometry>
        <cylinder radius="0.05" length="0.04" />
      </geometry>
      <material name="blue" />
    </visual>
    <collision>
      <geometry>
        <cylinder radius="0.05" length="0.04" />
      </geometry>
    </collision>
    <inertial>
      <mass value="0.1" />
      <inertia ixx="0.0002" ixy="0" ixz="0"
        iyy="0.0002" iyz="0"
        izz="0.0002" />
    </inertial>
  </link>

  <!-- Right wheel -->
  <joint name="right_wheel_joint" type="continuous">
    <parent link="base_link" />
    <child link="right_wheel" />
    <origin xyz="0 -0.175 0.05" rpy="-1.5708 0 0" />
    <axis xyz="0 0 1" />
  </joint>

  <link name="right_wheel">
    <visual>
      <geometry>
        <cylinder radius="0.05" length="0.04" />
      </geometry>
      <material name="blue" />
    </visual>
    <collision>
      <geometry>
        <cylinder radius="0.05" length="0.04" />
      </geometry>
    </collision>
    <inertial>
      <mass value="0.1" />
      <inertia ixx="0.0002" ixy="0" ixz="0"
        iyy="0.0002" iyz="0"
        izz="0.0002" />
    </inertial>
  </link>

  <!-- Gazebo Diff Drive Plugin -->
  <gazebo>
    <plugin filename="libgz-sim8-diff-drive-system.so" name="gz::sim::systems::DiffDrive">
      <left_joint>left_wheel_joint</left_joint>
      <right_joint>right_wheel_joint</right_joint>
      <wheel_separation>0.35</wheel_separation>
      <wheel_radius>0.05</wheel_radius>
      <odom_publish_frequency>50</odom_publish_frequency>
      <topic>cmd_vel</topic>
      <odom_topic>odom</odom_topic>
      <frame_id>odom</frame_id>
      <child_frame_id>base_link</child_frame_id>
    </plugin>
  </gazebo>

</robot>